Workbook
Name Slicer_Status: #N/A

Sheet تليل المبيعات الشهرية
A1: Status | B1: Completed
A3: Row Labels | B3: Sum of NetSales_egp
A4: 44927 | B4: 2753350.2
A5: 44958 | B5: 1036006.1
A6: 44986 | B6: 1584053.1
A7: 45017 | B7: 1781653.3
A8: 45047 | B8: 2300130
A9: 45078 | B9: 1479443.4
A10: 45108 | B10: 1372526.8
A11: 45139 | B11: 1131511.2
A12: 45170 | B12: 1510855.4
A13: 45200 | B13: 2510591.5
A14: 45231 | B14: 2055964.4
A15: 45261 | B15: 2093059.6
... A39: 45992 | B39: 2376183.3
A40: Grand Total | B40: 68776978

Sheet تحليل المبيعات بالنسبة للمدينة
A1: Status | B1: Completed
A3: Row Labels | B3: Sum of NetSales_egp
A4: Alexandria | B4: 8664153.5
A5: Zagazig | B5: 8391452.7
A6: Tanta | B6: 6634868.9
A7: Asyut | B7: 6434873.5
A8: Banha | B8: 5716747.7
A9: Fayoum | B9: 5331782.7
A10: Mansoura | B10: 5272377.2
A11: Giza | B11: 5131835.4
A12: Port Said | B12: 4791285.3
A13: Shubra El-Kheima | B13: 4546435
A14: Ismailia | B14: 4046797.3
A15: Cairo | B15: 3814368.3
A16: Grand Total | B16: 68776978

Sheet تحليل المبيعات بالنسبة للعملاء
A1: Status | B1: Completed
A3: Row Labels | B3: Sum of NetSales_egp
A4: Consumer | B4: 35208968
A5: Small Business | B5: 21705564
A6: Corporate | B6: 11862445
A7: Grand Total | B7: 68776978

Sheet Sheet6
A1: Status | B1: Completed
A3: Row Labels | B3: Sum of NetSales_egp
A4: Notebook Pack | B4: 260915.53
A5: Paper A4 Box | B5: 385771.83
A6: Wireless Mouse | B6: 472010.58
A7: Barcode Scanner | B7: 571001.35
A8: USB-C Hub | B8: 751608.62
A9: Printer Toner | B9: 755286.49
A10: Webcam HD | B10: 805474.28
A11: Headset Pro | B11: 820795.5
A12: Wi-Fi Router | B12: 849695.53
A13: Mechanical Keyboard | B13: 1177376.3
A14: Filing Cabinet | B14: 1559021.5
A15: External SSD 1TB | B15: 1675371.2
... A24: Grand Total | B24: 68776978

Sheet Sheet7
A1: Status | B1: Completed
A3: Row Labels | B3: Sum of GrossProfit_egp
A4: Laptop Pro 14 | B4: 4386051.9
A5: Laptop Basic 15 | B5: 2473254.7
A6: 27-inch Monitor | B6: 1390835.9
A7: Office Chair | B7: 822516.24
A8: Standing Desk | B8: 749178.24
A9: Laser Printer | B9: 542866.1
A10: Mechanical Keyboard | B10: 503186.26
A11: Projector | B11: 493542.56
A12: UPS 1200VA | B12: 490803.22
A13: Filing Cabinet | B13: 448671.49
A14: External SSD 1TB | B14: 416071.24
A15: USB-C Hub | B15: 346128.62
... A24: Grand Total | B24: 15116523

Sheet Sales_Raw
A1: OrderID | B1: OrderDate | C1: CustomerID | D1: ProductID | E1: Quantity | F1: UnitPrice_EGP | G1: DiscountRate | H1: Status | I1: ShipDays | J1: NetSales_egp | K1: OrderMonth | L1: city | M1: Segment | N1: Product name | O1: Category | P1: Sub Category | Q1: UnitCost_egp | R1: TotalCost_EGP | S1: GrossProfit_egp
A2: ORD100000 | B2: 45254 | C2: C0286 | D2: P001 | E2: 2 | F2: 28500 | G2: 0.15 | H2: Completed | I2: 4 | J2: =E2*F2*(1-G2) -> 48450 | K2: =DATE(YEAR(B2),MONTH(B2),1) -> 45231 | L2: =VLOOKUP(C2,Customers!$A$2:$F$401,3,FALSE) -> Shubra El-Kheima | M2: =VLOOKUP(C2,Customers!$A$2:$F$401,5,FALSE) -> Consumer | N2: =VLOOKUP(D2,Products!$A$2:$F$21,2,FALSE) -> Laptop Pro 14 | O2: =VLOOKUP(D2,Products!$A$2:$F$21,4,FALSE) -> Electronics | P2: =VLOOKUP(D2,Products!$A$2:$F$21,3,FALSE) -> Computers | Q2: =VLOOKUP(D2,Products!$A$2:$F$21,6,FALSE) -> 22100 | R2: =E2*Q2 -> 44200 | S2: =J2-R2 -> 4250
A3: ORD100001 | B3: 44990 | C3: C0367 | D3: P003 | E3: 1 | F3: 414 | G3: 0.05 | H3: Completed | I3: 5 | J3: =E3*F3*(1-G3) -> 393.3 | K3: =DATE(YEAR(B3),MONTH(B3),1) -> 44986 | L3: =VLOOKUP(C3,Customers!$A$2:$F$401,3,FALSE) -> Giza | M3: =VLOOKUP(C3,Customers!$A$2:$F$401,5,FALSE) -> Consumer | N3: =VLOOKUP(D3,Products!$A$2:$F$21,2,FALSE) -> Wireless Mouse | O3: =VLOOKUP(D3,Products!$A$2:$F$21,4,FALSE) -> Electronics | P3: =VLOOKUP(D3,Products!$A$2:$F$21,3,FALSE) -> Accessories | Q3: =VLOOKUP(D3,Products!$A$2:$F$21,6,FALSE) -> 210 | R3: =E3*Q3 -> 210 | S3: =J3-R3 -> 183.3 | U3: =SUMIF(H2:H5001,"COMPLETED",J2:J5001) -> 68776978 | V3: اجمالي المبيعات المكتملة
A4: ORD100002 | B4: 45219 | C4: C0293 | D4: P013 | E4: 2 | F4: 1566 | G4: 0.15 | H4: Completed | I4: 4 | J4: =E4*F4*(1-G4) -> 2662.2 | K4: =DATE(YEAR(B4),MONTH(B4),1) -> 45200 | L4: =VLOOKUP(C4,Customers!$A$2:$F$401,3,FALSE) -> Port Said | M4: =VLOOKUP(C4,Customers!$A$2:$F$401,5,FALSE) -> Consumer | N4: =VLOOKUP(D4,Products!$A$2:$F$21,2,FALSE) -> Webcam HD | O4: =VLOOKUP(D4,Products!$A$2:$F$21,4,FALSE) -> Electronics | P4: =VLOOKUP(D4,Products!$A$2:$F$21,3,FALSE) -> Accessories | Q4: =VLOOKUP(D4,Products!$A$2:$F$21,6,FALSE) -> 790 | R4: =E4*Q4 -> 1580 | S4: =J4-R4 -> 1082.2 | U4: =COUNTIF(H2:H5001,"COMPLETED") -> 4419 | V4: عدد طلبات البيع المكتملة
A5: ORD100003 | B5: 45824 | C5: C0303 | D5: P004 | E5: 20 | F5: 1998 | G5: 0.1 | H5: Completed | I5: 3 | J5: =E5*F5*(1-G5) -> 35964 | K5: =DATE(YEAR(B5),MONTH(B5),1) -> 45809 | L5: =VLOOKUP(C5,Customers!$A$2:$F$401,3,FALSE) -> Tanta | M5: =VLOOKUP(C5,Customers!$A$2:$F$401,5,FALSE) -> Consumer | N5: =VLOOKUP(D5,Products!$A$2:$F$21,2,FALSE) -> Mechanical Keyboard | O5: =VLOOKUP(D5,Products!$A$2:$F$21,4,FALSE) -> Electronics | P5: =VLOOKUP(D5,Products!$A$2:$F$21,3,FALSE) -> Accessories | Q5: =VLOOKUP(D5,Products!$A$2:$F$21,6,FALSE) -> 990 | R5: =E5*Q5 -> 19800 | S5: =J5-R5 -> 16164
A6: ORD100004 | B6: 44998 | C6: C0015 | D6: P006 | E6: 2 | F6: 1212.5 | G6: 0.1 | H6: Completed | I6: 6 | J6: =E6*F6*(1-G6) -> 2182.5 | K6: =DATE(YEAR(B6),MONTH(B6),1) -> 44986 | L6: =VLOOKUP(C6,Customers!$A$2:$F$401,3,FALSE) -> Tanta | M6: =VLOOKUP(C6,Customers!$A$2:$F$401,5,FALSE) -> Consumer | N6: =VLOOKUP(D6,Products!$A$2:$F$21,2,FALSE) -> USB-C Hub | O6: =VLOOKUP(D6,Products!$A$2:$F$21,4,FALSE) -> Electronics | P6: =VLOOKUP(D6,Products!$A$2:$F$21,3,FALSE) -> Accessories | Q6: =VLOOKUP(D6,Products!$A$2:$F$21,6,FALSE) -> 620 | R6: =E6*Q6 -> 1240 | S6: =J6-R6 -> 942.5 | U6: =AVERAGEIF(H2:H5001,"COMPLETED",J2:J5001) -> 15563.923 | V6: متوسط قيمة الطلب المكتملة
A7: ORD100005 | B7: 45185 | C7: C0392 | D7: P011 | E7: 5 | F7: 980 | G7: 0.03 | H7: Completed | I7: 3 | J7: =E7*F7*(1-G7) -> 4753 | K7: =DATE(YEAR(B7),MONTH(B7),1) -> 45170 | L7: =VLOOKUP(C7,Customers!$A$2:$F$401,3,FALSE) -> Mansoura | M7: =VLOOKUP(C7,Customers!$A$2:$F$401,5,FALSE) -> Consumer | N7: =VLOOKUP(D7,Products!$A$2:$F$21,2,FALSE) -> Printer Toner | O7: =VLOOKUP(D7,Products!$A$2:$F$21,4,FALSE) -> Office | P7: =VLOOKUP(D7,Products!$A$2:$F$21,3,FALSE) -> Supplies | Q7: =VLOOKUP(D7,Products!$A$2:$F$21,6,FALSE) -> 510 | R7: =E7*Q7 -> 2550 | S7: =J7-R7 -> 2203
A8: ORD100006 | B8: 45064 | C8: C0029 | D8: P008 | E8: 2 | F8: 8924 | G8: 0 | H8: Completed | I8: 1 | J8: =E8*F8*(1-G8) -> 17848 | K8: =DATE(YEAR(B8),MONTH(B8),1) -> 45047 | L8: =VLOOKUP(C8,Customers!$A$2:$F$401,3,FALSE) -> Zagazig | M8: =VLOOKUP(C8,Customers!$A$2:$F$401,5,FALSE) -> Small Business | N8: =VLOOKUP(D8,Products!$A$2:$F$21,2,FALSE) -> Standing Desk | O8: =VLOOKUP(D8,Products!$A$2:$F$21,4,FALSE) -> Office | P8: =VLOOKUP(D8,Products!$A$2:$F$21,3,FALSE) -> Furniture | Q8: =VLOOKUP(D8,Products!$A$2:$F$21,6,FALSE) -> 6500 | R8: =E8*Q8 -> 13000 | S8: =J8-R8 -> 4848 | U8: =SUM(J2:J5001) -> 76682344 | V8: اجمالي قيمة كل العمليات
A9: ORD100007 | B9: 45410 | C9: C0034 | D9: P017 | E9: 4 | F9: 3588 | G9: 0.03 | H9: Completed | I9: 3 | J9: =E9*F9*(1-G9) -> 13921.44 | K9: =DATE(YEAR(B9),MONTH(B9),1) -> 45383 | L9: =VLOOKUP(C9,Customers!$A$2:$F$401,3,FALSE) -> Tanta | M9: =VLOOKUP(C9,Customers!$A$2:$F$401,5,FALSE) -> Consumer | N9: =VLOOKUP(D9,Products!$A$2:$F$21,2,FALSE) -> Filing Cabinet | O9: =VLOOKUP(D9,Products!$A$2:$F$21,4,FALSE) -> Office | P9: =VLOOKUP(D9,Products!$A$2:$F$21,3,FALSE) -> Furniture | Q9: =VLOOKUP(D9,Products!$A$2:$F$21,6,FALSE) -> 2650 | R9: =E9*Q9 -> 10600 | S9: =J9-R9 -> 3321.44 | U9: =SUMIF(H2:H5001,"CANCELLED",J2:J5001) -> 4510592.1 | V9: قيمة الطلبات الملغية
A10: ORD100008 | B10: 45677 | C10: C0337 | D10: P001 | E10: 4 | F10: 30780 | G10: 0.05 | H10: Completed | I10: 1 | J10: =E10*F10*(1-G10) -> 116964 | K10: =DATE(YEAR(B10),MONTH(B10),1) -> 45658 | L10: =VLOOKUP(C10,Customers!$A$2:$F$401,3,FALSE) -> Asyut | M10: =VLOOKUP(C10,Customers!$A$2:$F$401,5,FALSE) -> Consumer | N10: =VLOOKUP(D10,Products!$A$2:$F$21,2,FALSE) -> Laptop Pro 14 | O10: =VLOOKUP(D10,Products!$A$2:$F$21,4,FALSE) -> Electronics | P10: =VLOOKUP(D10,Products!$A$2:$F$21,3,FALSE) -> Computers | Q10: =VLOOKUP(D10,Products!$A$2:$F$21,6,FALSE) -> 22100 | R10: =E10*Q10 -> 88400 | S10: =J10-R10 -> 28564 | U10: =SUMIF(H2:H5001,"RETURNED",J2:J5001) -> 3394774.7 | V10: قيمة الطلبات المرتجعة
A11: ORD100009 | B11: 45668 | C11: C0302 | D11: P013 | E11: 1 | F11: 1450 | G11: 0.03 | H11: Completed | I11: 5 | J11: =E11*F11*(1-G11) -> 1406.5 | K11: =DATE(YEAR(B11),MONTH(B11),1) -> 45658 | L11: =VLOOKUP(C11,Customers!$A$2:$F$401,3,FALSE) -> Port Said | M11: =VLOOKUP(C11,Customers!$A$2:$F$401,5,FALSE) -> Consumer | N11: =VLOOKUP(D11,Products!$A$2:$F$21,2,FALSE) -> Webcam HD | O11: =VLOOKUP(D11,Products!$A$2:$F$21,4,FALSE) -> Electronics | P11: =VLOOKUP(D11,Products!$A$2:$F$21,3,FALSE) -> Accessories | Q11: =VLOOKUP(D11,Products!$A$2:$F$21,6,FALSE) -> 790 | R11: =E11*Q11 -> 790 | S11: =J11-R11 -> 616.5 | U11: =SUMIF(H2:H5001,"COMPLETED",J2:J5001)+SUMIF(H2:H5001,"CANCELLED",J2:J5001)+SUMIF(H2:H5001,"RETURNED",J2:J5001)-SUM(J2:J5001) -> 0
A12: ORD100010 | B12: 45711 | C12: C0251 | D12: P002 | E12: 1 | F12: 18915 | G12: 0.03 | H12: Completed | I12: 7 | J12: =E12*F12*(1-G12) -> 18347.55 | K12: =DATE(YEAR(B12),MONTH(B12),1) -> 45689 | L12: =VLOOKUP(C12,Customers!$A$2:$F$401,3,FALSE) -> Giza | M12: =VLOOKUP(C12,Customers!$A$2:$F$401,5,FALSE) -> Consumer | N12: =VLOOKUP(D12,Products!$A$2:$F$21,2,FALSE) -> Laptop Basic 15 | O12: =VLOOKUP(D12,Products!$A$2:$F$21,4,FALSE) -> Electronics | P12: =VLOOKUP(D12,Products!$A$2:$F$21,3,FALSE) -> Computers | Q12: =VLOOKUP(D12,Products!$A$2:$F$21,6,FALSE) -> 15100 | R12: =E12*Q12 -> 15100 | S12: =J12-R12 -> 3247.55 | U12: =COUNTIF(H2:H5001,"CANCELLED") -> 334 | V12: عدد الطلبات الملغية
A13: ORD100011 | B13: 44993 | C13: C0086 | D13: P012 | E13: 2 | F13: 3600 | G13: 0.2 | H13: Completed | I13: 6 | J13: =E13*F13*(1-G13) -> 5760 | K13: =DATE(YEAR(B13),MONTH(B13),1) -> 44986 | L13: =VLOOKUP(C13,Customers!$A$2:$F$401,3,FALSE) -> Tanta | M13: =VLOOKUP(C13,Customers!$A$2:$F$401,5,FALSE) -> Small Business | N13: =VLOOKUP(D13,Products!$A$2:$F$21,2,FALSE) -> External SSD 1TB | O13: =VLOOKUP(D13,Products!$A$2:$F$21,4,FALSE) -> Electronics | P13: =VLOOKUP(D13,Products!$A$2:$F$21,3,FALSE) -> Storage | Q13: =VLOOKUP(D13,Products!$A$2:$F$21,6,FALSE) -> 2450 | R13: =E13*Q13 -> 4900 | S13: =J13-R13 -> 860 | U13: =COUNTIF(H2:H5001,"RETURNED") -> 247 | V13: عدد الطلبات المرتجعة
A14: ORD100012 | B14: 45241 | C14: C0039 | D14: P016 | E14: 4 | F14: 280.8 | G14: 0 | H14: Completed | I14: 3 | J14: =E14*F14*(1-G14) -> 1123.2 | K14: =DATE(YEAR(B14),MONTH(B14),1) -> 45231 | L14: =VLOOKUP(C14,Customers!$A$2:$F$401,3,FALSE) -> Zagazig | M14: =VLOOKUP(C14,Customers!$A$2:$F$401,5,FALSE) -> Small Business | N14: =VLOOKUP(D14,Products!$A$2:$F$21,2,FALSE) -> Paper A4 Box | O14: =VLOOKUP(D14,Products!$A$2:$F$21,4,FALSE) -> Office | P14: =VLOOKUP(D14,Products!$A$2:$F$21,3,FALSE) -> Stationery | Q14: =VLOOKUP(D14,Products!$A$2:$F$21,6,FALSE) -> 145 | R14: =E14*Q14 -> 580 | S14: =J14-R14 -> 543.2 | U14: =COUNTIF(H2:H5001,"COMPLETED")/COUNTA(H2:H5001) -> 0.8838 | V14: نسبة الطلبات المكتملة
A15: ORD100013 | B15: 45848 | C15: C0206 | D15: P020 | E15: 3 | F15: 4428 | G15: 0.1 | H15: Completed | I15: 7 | J15: =E15*F15*(1-G15) -> 11955.6 | K15: =DATE(YEAR(B15),MONTH(B15),1) -> 45839 | L15: =VLOOKUP(C15,Customers!$A$2:$F$401,3,FALSE) -> Shubra El-Kheima | M15: =VLOOKUP(C15,Customers!$A$2:$F$401,5,FALSE) -> Small Business | N15: =VLOOKUP(D15,Products!$A$2:$F$21,2,FALSE) -> UPS 1200VA | O15: =VLOOKUP(D15,Products!$A$2:$F$21,4,FALSE) -> Electronics | P15: =VLOOKUP(D15,Products!$A$2:$F$21,3,FALSE) -> Power | Q15: =VLOOKUP(D15,Products!$A$2:$F$21,6,FALSE) -> 2950 | R15: =E15*Q15 -> 8850 | S15: =J15-R15 -> 3105.6 | U15: =COUNTIF(H2:H5001,"CANCELLED")/COUNTA(H2:H5001) -> 0.0668 | V15: نسبة الطلبات الملغاة
A16: ORD100014 | B16: 45686 | C16: C0304 | D16: P011 | E16: 1 | F16: 901.6 | G16: 0.05 | H16: Completed | I16: 4 | J16: =E16*F16*(1-G16) -> 856.52 | K16: =DATE(YEAR(B16),MONTH(B16),1) -> 45658 | L16: =VLOOKUP(C16,Customers!$A$2:$F$401,3,FALSE) -> Fayoum | M16: =VLOOKUP(C16,Customers!$A$2:$F$401,5,FALSE) -> Small Business | N16: =VLOOKUP(D16,Products!$A$2:$F$21,2,FALSE) -> Printer Toner | O16: =VLOOKUP(D16,Products!$A$2:$F$21,4,FALSE) -> Office | P16: =VLOOKUP(D16,Products!$A$2:$F$21,3,FALSE) -> Supplies | Q16: =VLOOKUP(D16,Products!$A$2:$F$21,6,FALSE) -> 510 | R16: =E16*Q16 -> 510 | S16: =J16-R16 -> 346.52 | U16: =COUNTIF(H2:H5001,"RETURNED")/COUNTA(H2:H5001) -> 0.0494 | V16: نسية الطلبات المرتجعة
A17: ORD100015 | B17: 45688 | C17: C0040 | D17: P003 | E17: 2 | F17: 450 | G17: 0.05 | H17: Completed | I17: 6 | J17: =E17*F17*(1-G17) -> 855 | K17: =DATE(YEAR(B17),MONTH(B17),1) -> 45658 | L17: =VLOOKUP(C17,Customers!$A$2:$F$401,3,FALSE) -> Asyut | M17: =VLOOKUP(C17,Customers!$A$2:$F$401,5,FALSE) -> Small Business | N17: =VLOOKUP(D17,Products!$A$2:$F$21,2,FALSE) -> Wireless Mouse | O17: =VLOOKUP(D17,Products!$A$2:$F$21,4,FALSE) -> Electronics | P17: =VLOOKUP(D17,Products!$A$2:$F$21,3,FALSE) -> Accessories | Q17: =VLOOKUP(D17,Products!$A$2:$F$21,6,FALSE) -> 210 | R17: =E17*Q17 -> 420 | S17: =J17-R17 -> 435 | U17: =AVERAGE(I2:I5001) -> 4.0138 | V17: average ship days
A18: ORD100016 | B18: 45836 | C18: C0103 | D18: P009 | E18: 1 | F18: 180 | G18: 0.05 | H18: Completed | I18: 7 | J18: =E18*F18*(1-G18) -> 171 | K18: =DATE(YEAR(B18),MONTH(B18),1) -> 45809 | L18: =VLOOKUP(C18,Customers!$A$2:$F$401,3,FALSE) -> Fayoum | M18: =VLOOKUP(C18,Customers!$A$2:$F$401,5,FALSE) -> Consumer | N18: =VLOOKUP(D18,Products!$A$2:$F$21,2,FALSE) -> Notebook Pack | O18: =VLOOKUP(D18,Products!$A$2:$F$21,4,FALSE) -> Office | P18: =VLOOKUP(D18,Products!$A$2:$F$21,3,FALSE) -> Stationery | Q18: =VLOOKUP(D18,Products!$A$2:$F$21,6,FALSE) -> 75 | R18: =E18*Q18 -> 75 | S18: =J18-R18 -> 96 | U18: =AVERAGEIF(H2:H5001,"COMPLETED",I2:I5001) -> 4.0201403 | V18: average ship days completed
A19: ORD100017 | B19: 45084 | C19: C0010 | D19: P010 | E19: 2 | F19: 7992 | G19: 0.15 | H19: Completed | I19: 2 | J19: =E19*F19*(1-G19) -> 13586.4 | K19: =DATE(YEAR(B19),MONTH(B19),1) -> 45078 | L19: =VLOOKUP(C19,Customers!$A$2:$F$401,3,FALSE) -> Giza | M19: =VLOOKUP(C19,Customers!$A$2:$F$401,5,FALSE) -> Corporate | N19: =VLOOKUP(D19,Products!$A$2:$F$21,2,FALSE) -> Laser Printer | O19: =VLOOKUP(D19,Products!$A$2:$F$21,4,FALSE) -> Electronics | P19: =VLOOKUP(D19,Products!$A$2:$F$21,3,FALSE) -> Printers | Q19: =VLOOKUP(D19,Products!$A$2:$F$21,6,FALSE) -> 5600 | R19: =E19*Q19 -> 11200 | S19: =J19-R19 -> 2386.4 | U19: =SUMIF(H2:H5001,"COMPLETED",S2:S5001) -> 15116523 | V19: total gross profit
A20: ORD100018 | B20: 45208 | C20: C0381 | D20: P012 | E20: 5 | F20: 3600 | G20: 0.15 | H20: Completed | I20: 5 | J20: =E20*F20*(1-G20) -> 15300 | K20: =DATE(YEAR(B20),MONTH(B20),1) -> 45200 | L20: =VLOOKUP(C20,Customers!$A$2:$F$401,3,FALSE) -> Asyut | M20: =VLOOKUP(C20,Customers!$A$2:$F$401,5,FALSE) -> Consumer | N20: =VLOOKUP(D20,Products!$A$2:$F$21,2,FALSE) -> External SSD 1TB | O20: =VLOOKUP(D20,Products!$A$2:$F$21,4,FALSE) -> Electronics | P20: =VLOOKUP(D20,Products!$A$2:$F$21,3,FALSE) -> Storage | Q20: =VLOOKUP(D20,Products!$A$2:$F$21,6,FALSE) -> 2450 | R20: =E20*Q20 -> 12250 | S20: =J20-R20 -> 3050
A21: ORD100019 | B21: 46011 | C21: C0223 | D21: P016 | E21: 5 | F21: 239.2 | G21: 0.05 | H21: Completed | I21: 2 | J21: =E21*F21*(1-G21) -> 1136.2 | K21: =DATE(YEAR(B21),MONTH(B21),1) -> 45992 | L21: =VLOOKUP(C21,Customers!$A$2:$F$401,3,FALSE) -> Banha | M21: =VLOOKUP(C21,Customers!$A$2:$F$401,5,FALSE) -> Consumer | N21: =VLOOKUP(D21,Products!$A$2:$F$21,2,FALSE) -> Paper A4 Box | O21: =VLOOKUP(D21,Products!$A$2:$F$21,4,FALSE) -> Office | P21: =VLOOKUP(D21,Products!$A$2:$F$21,3,FALSE) -> Stationery | Q21: =VLOOKUP(D21,Products!$A$2:$F$21,6,FALSE) -> 145 | R21: =E21*Q21 -> 725 | S21: =J21-R21 -> 411.2
A22: ORD100020 | B22: 45678 | C22: C0383 | D22: P004 | E22: 3 | F22: 1850 | G22: 0.15 | H22: Completed | I22: 7 | J22: =E22*F22*(1-G22) -> 4717.5 | K22: =DATE(YEAR(B22),MONTH(B22),1) -> 45658 | L22: =VLOOKUP(C22,Customers!$A$2:$F$401,3,FALSE) -> Port Said | M22: =VLOOKUP(C22,Customers!$A$2:$F$401,5,FALSE) -> Small Business | N22: =VLOOKUP(D22,Products!$A$2:$F$21,2,FALSE) -> Mechanical Keyboard | O22: =VLOOKUP(D22,Products!$A$2:$F$21,4,FALSE) -> Electronics | P22: =VLOOKUP(D22,Products!$A$2:$F$21,3,FALSE) -> Accessories | Q22: =VLOOKUP(D22,Products!$A$2:$F$21,6,FALSE) -> 990 | R22: =E22*Q22 -> 2970 | S22: =J22-R22 -> 1747.5
A23: ORD100021 | B23: 45742 | C23: C0033 | D23: P016 | E23: 2 | F23: 267.8 | G23: 0 | H23: Completed | I23: 2 | J23: =E23*F23*(1-G23) -> 535.6 | K23: =DATE(YEAR(B23),MONTH(B23),1) -> 45717 | L23: =VLOOKUP(C23,Customers!$A$2:$F$401,3,FALSE) -> Banha | M23: =VLOOKUP(C23,Customers!$A$2:$F$401,5,FALSE) -> Consumer | N23: =VLOOKUP(D23,Products!$A$2:$F$21,2,FALSE) -> Paper A4 Box | O23: =VLOOKUP(D23,Products!$A$2:$F$21,4,FALSE) -> Office | P23: =VLOOKUP(D23,Products!$A$2:$F$21,3,FALSE) -> Stationery | Q23: =VLOOKUP(D23,Products!$A$2:$F$21,6,FALSE) -> 145 | R23: =E23*Q23 -> 290 | S23: =J23-R23 -> 245.6
A24: ORD100022 | B24: 45570 | C24: C0308 | D24: P004 | E24: 1 | F24: 1794.5 | G24: 0 | H24: Completed | I24: 2 | J24: =E24*F24*(1-G24) -> 1794.5 | K24: =DATE(YEAR(B24),MONTH(B24),1) -> 45566 | L24: =VLOOKUP(C24,Customers!$A$2:$F$401,3,FALSE) -> Mansoura | M24: =VLOOKUP(C24,Customers!$A$2:$F$401,5,FALSE) -> Consumer | N24: =VLOOKUP(D24,Products!$A$2:$F$21,2,FALSE) -> Mechanical Keyboard | O24: =VLOOKUP(D24,Products!$A$2:$F$21,4,FALSE) -> Electronics | P24: =VLOOKUP(D24,Products!$A$2:$F$21,3,FALSE) -> Accessories | Q24: =VLOOKUP(D24,Products!$A$2:$F$21,6,FALSE) -> 990 | R24: =E24*Q24 -> 990 | S24: =J24-R24 -> 804.5
A25: ORD100023 | B25: 45497 | C25: C0159 | D25: P015 | E25: 2 | F25: 1890 | G25: 0.2 | H25: Completed | I25: 1 | J25: =E25*F25*(1-G25) -> 3024 | K25: =DATE(YEAR(B25),MONTH(B25),1) -> 45474 | L25: =VLOOKUP(C25,Customers!$A$2:$F$401,3,FALSE) -> Mansoura | M25: =VLOOKUP(C25,Customers!$A$2:$F$401,5,FALSE) -> Consumer | N25: =VLOOKUP(D25,Products!$A$2:$F$21,2,FALSE) -> Wi-Fi Router | O25: =VLOOKUP(D25,Products!$A$2:$F$21,4,FALSE) -> Electronics | P25: =VLOOKUP(D25,Products!$A$2:$F$21,3,FALSE) -> Networking | Q25: =VLOOKUP(D25,Products!$A$2:$F$21,6,FALSE) -> 1050 | R25: =E25*Q25 -> 2100 | S25: =J25-R25 -> 924
A26: ORD100024 | B26: 45438 | C26: C0140 | D26: P003 | E26: 1 | F26: 450 | G26: 0.1 | H26: Completed | I26: 5 | J26: =E26*F26*(1-G26) -> 405 | K26: =DATE(YEAR(B26),MONTH(B26),1) -> 45413 | L26: =VLOOKUP(C26,Customers!$A$2:$F$401,3,FALSE) -> Ismailia | M26: =VLOOKUP(C26,Customers!$A$2:$F$401,5,FALSE) -> Small Business | N26: =VLOOKUP(D26,Products!$A$2:$F$21,2,FALSE) -> Wireless Mouse | O26: =VLOOKUP(D26,Products!$A$2:$F$21,4,FALSE) -> Electronics | P26: =VLOOKUP(D26,Products!$A$2:$F$21,3,FALSE) -> Accessories | Q26: =VLOOKUP(D26,Products!$A$2:$F$21,6,FALSE) -> 210 | R26: =E26*Q26 -> 210 | S26: =J26-R26 -> 195
A27: ORD100025 | B27: 45159 | C27: C0022 | D27: P003 | E27: 10 | F27: 463.5 | G27: 0.1 | H27: Completed | I27: 1 | J27: =E27*F27*(1-G27) -> 4171.5 | K27: =DATE(YEAR(B27),MONTH(B27),1) -> 45139 | L27: =VLOOKUP(C27,Customers!$A$2:$F$401,3,FALSE) -> Banha | M27: =VLOOKUP(C27,Customers!$A$2:$F$401,5,FALSE) -> Consumer | N27: =VLOOKUP(D27,Products!$A$2:$F$21,2,FALSE) -> Wireless Mouse | O27: =VLOOKUP(D27,Products!$A$2:$F$21,4,FALSE) -> Electronics | P27: =VLOOKUP(D27,Products!$A$2:$F$21,3,FALSE) -> Accessories | Q27: =VLOOKUP(D27,Products!$A$2:$F$21,6,FALSE) -> 210 | R27: =E27*Q27 -> 2100 | S27: =J27-R27 -> 2071.5
A28: ORD100026 | B28: 44980 | C28: C0153 | D28: P005 | E28: 4 | F28: 6386 | G28: 0.15 | H28: Completed | I28: 1 | J28: =E28*F28*(1-G28) -> 21712.4 | K28: =DATE(YEAR(B28),MONTH(B28),1) -> 44958 | L28: =VLOOKUP(C28,Customers!$A$2:$F$401,3,FALSE) -> Giza | M28: =VLOOKUP(C28,Customers!$A$2:$F$401,5,FALSE) -> Consumer | N28: =VLOOKUP(D28,Products!$A$2:$F$21,2,FALSE) -> 27-inch Monitor | O28: =VLOOKUP(D28,Products!$A$2:$F$21,4,FALSE) -> Electronics | P28: =VLOOKUP(D28,Products!$A$2:$F$21,3,FALSE) -> Displays | Q28: =VLOOKUP(D28,Products!$A$2:$F$21,6,FALSE) -> 4300 | R28: =E28*Q28 -> 17200 | S28: =J28-R28 -> 4512.4
A29: ORD100027 | B29: 45308 | C29: C0371 | D29: P007 | E29: 4 | F29: 4656 | G29: 0 | H29: Completed | I29: 1 | J29: =E29*F29*(1-G29) -> 18624 | K29: =DATE(YEAR(B29),MONTH(B29),1) -> 45292 | L29: =VLOOKUP(C29,Customers!$A$2:$F$401,3,FALSE) -> Giza | M29: =VLOOKUP(C29,Customers!$A$2:$F$401,5,FALSE) -> Consumer | N29: =VLOOKUP(D29,Products!$A$2:$F$21,2,FALSE) -> Office Chair | O29: =VLOOKUP(D29,Products!$A$2:$F$21,4,FALSE) -> Office | P29: =VLOOKUP(D29,Products!$A$2:$F$21,3,FALSE) -> Furniture | Q29: =VLOOKUP(D29,Products!$A$2:$F$21,6,FALSE) -> 3150 | R29: =E29*Q29 -> 12600 | S29: =J29-R29 -> 6024
A30: ORD100028 | B30: 45949 | C30: C0298 | D30: P009 | E30: 10 | F30: 194.4 | G30: 0 | H30: Cancelled | I30: 2 | J30: =E30*F30*(1-G30) -> 1944 | K30: =DATE(YEAR(B30),MONTH(B30),1) -> 45931 | L30: =VLOOKUP(C30,Customers!$A$2:$F$401,3,FALSE) -> Asyut | M30: =VLOOKUP(C30,Customers!$A$2:$F$401,5,FALSE) -> Small Business | N30: =VLOOKUP(D30,Products!$A$2:$F$21,2,FALSE) -> Notebook Pack | O30: =VLOOKUP(D30,Products!$A$2:$F$21,4,FALSE) -> Office | P30: =VLOOKUP(D30,Products!$A$2:$F$21,3,FALSE) -> Stationery | Q30: =VLOOKUP(D30,Products!$A$2:$F$21,6,FALSE) -> 75 | R30: =E30*Q30 -> 750 | S30: =J30-R30 -> 1194
A31: ORD100029 | B31: 45987 | C31: C0396 | D31: P011 | E31: 3 | F31: 980 | G31: 0.1 | H31: Completed | I31: 7 | J31: =E31*F31*(1-G31) -> 2646 | K31: =DATE(YEAR(B31),MONTH(B31),1) -> 45962 | L31: =VLOOKUP(C31,Customers!$A$2:$F$401,3,FALSE) -> Tanta | M31: =VLOOKUP(C31,Customers!$A$2:$F$401,5,FALSE) -> Small Business | N31: =VLOOKUP(D31,Products!$A$2:$F$21,2,FALSE) -> Printer Toner | O31: =VLOOKUP(D31,Products!$A$2:$F$21,4,FALSE) -> Office | P31: =VLOOKUP(D31,Products!$A$2:$F$21,3,FALSE) -> Supplies | Q31: =VLOOKUP(D31,Products!$A$2:$F$21,6,FALSE) -> 510 | R31: =E31*Q31 -> 1530 | S31: =J31-R31 -> 1116
... A4982: ORD104980 | B4982: 45935 | C4982: C0115 | D4982: P001 | E4982: 1 | F4982: 28500 | G4982: 0.1 | H4982: Completed | I4982: 6 | J4982: =E4982*F4982*(1-G4982) -> 25650 | K4982: =DATE(YEAR(B4982),MONTH(B4982),1) -> 45931 | L4982: =VLOOKUP(C4982,Customers!$A$2:$F$401,3,FALSE) -> Ismailia | M4982: =VLOOKUP(C4982,Customers!$A$2:$F$401,5,FALSE) -> Small Business | N4982: =VLOOKUP(D4982,Products!$A$2:$F$21,2,FALSE) -> Laptop Pro 14 | O4982: =VLOOKUP(D4982,Products!$A$2:$F$21,4,FALSE) -> Electronics | P4982: =VLOOKUP(D4982,Products!$A$2:$F$21,3,FALSE) -> Computers | Q4982: =VLOOKUP(D4982,Products!$A$2:$F$21,6,FALSE) -> 22100 | R4982: =E4982*Q4982 -> 22100 | S4982: =J4982-R4982 -> 3550
A4983: ORD104981 | B4983: 45881 | C4983: C0367 | D4983: P006 | E4983: 5 | F4983: 1150 | G4983: 0.1 | H4983: Completed | I4983: 4 | J4983: =E4983*F4983*(1-G4983) -> 5175 | K4983: =DATE(YEAR(B4983),MONTH(B4983),1) -> 45870 | L4983: =VLOOKUP(C4983,Customers!$A$2:$F$401,3,FALSE) -> Giza | M4983: =VLOOKUP(C4983,Customers!$A$2:$F$401,5,FALSE) -> Consumer | N4983: =VLOOKUP(D4983,Products!$A$2:$F$21,2,FALSE) -> USB-C Hub | O4983: =VLOOKUP(D4,Products!$A$2:$F$21,4,FALSE) -> Electronics | P4983: =VLOOKUP(D4983,Products!$A$2:$F$21,3,FALSE) -> Accessories | Q4983: =VLOOKUP(D4983,Products!$A$2:$F$21,6,FALSE) -> 620 | R4983: =E4983*Q4983 -> 3100 | S4983: =J4983-R4983 -> 2075
A4984: ORD104982 | B4984: 45340 | C4984: C0263 | D4984: P016 | E4984: 2 | F4984: 252.2 | G4984: 0 | H4984: Returned | I4984: 5 | J4984: =E4984*F4984*(1-G4984) -> 504.4 | K4984: =DATE(YEAR(B4984),MONTH(B4984),1) -> 45323 | L4984: =VLOOKUP(C4984,Customers!$A$2:$F$401,3,FALSE) -> Tanta | M4984: =VLOOKUP(C4984,Customers!$A$2:$F$401,5,FALSE) -> Consumer | N4984: =VLOOKUP(D4984,Products!$A$2:$F$21,2,FALSE) -> Paper A4 Box | O4984: =VLOOKUP(D5,Products!$A$2:$F$21,4,FALSE) -> Electronics | P4984: =VLOOKUP(D4984,Products!$A$2:$F$21,3,FALSE) -> Stationery | Q4984: =VLOOKUP(D4984,Products!$A$2:$F$21,6,FALSE) -> 145 | R4984: =E4984*Q4984 -> 290 | S4984: =J4984-R4984 -> 214.4
A4985: ORD104983 | B4985: 45528 | C4985: C0030 | D4985: P006 | E4985: 1 | F4985: 1350 | G4985: 0.05 | H4985: Completed | I4985: 3 | J4985: =E4985*F4985*(1-G4985) -> 1282.5 | K4985: =DATE(YEAR(B4985),MONTH(B4985),1) -> 45505 | L4985: =VLOOKUP(C4985,Customers!$A$2:$F$401,3,FALSE) -> Mansoura | M4985: =VLOOKUP(C4985,Customers!$A$2:$F$401,5,FALSE) -> Consumer | N4985: =VLOOKUP(D4985,Products!$A$2:$F$21,2,FALSE) -> USB-C Hub | O4985: =VLOOKUP(D6,Products!$A$2:$F$21,4,FALSE) -> Electronics | P4985: =VLOOKUP(D4985,Products!$A$2:$F$21,3,FALSE) -> Accessories | Q4985: =VLOOKUP(D4985,Products!$A$2:$F$21,6,FALSE) -> 620 | R4985: =E4985*Q4985 -> 620 | S4985: =J4985-R4985 -> 662.5
A4986: ORD104984 | B4986: 45946 | C4986: C0204 | D4986: P012 | E4986: 1 | F4986: 3312 | G4986: 0.05 | H4986: Completed | I4986: 6 | J4986: =E4986*F4986*(1-G4986) -> 3146.4 | K4986: =DATE(YEAR(B4986),MONTH(B4986),1) -> 45931 | L4986: =VLOOKUP(C4986,Customers!$A$2:$F$401,3,FALSE) -> Zagazig | M4986: =VLOOKUP(C4986,Customers!$A$2:$F$401,5,FALSE) -> Consumer | N4986: =VLOOKUP(D4986,Products!$A$2:$F$21,2,FALSE) -> External SSD 1TB | O4986: =VLOOKUP(D7,Products!$A$2:$F$21,4,FALSE) -> Office | P4986: =VLOOKUP(D4986,Products!$A$2:$F$21,3,FALSE) -> Storage | Q4986: =VLOOKUP(D4986,Products!$A$2:$F$21,6,FALSE) -> 2450 | R4986: =E4986*Q4986 -> 2450 | S4986: =J4986-R4986 -> 696.4
A4987: ORD104985 | B4987: 45931 | C4987: C0289 | D4987: P013 | E4987: 4 | F4987: 1406.5 | G4987: 0.1 | H4987: Completed | I4987: 2 | J4987: =E4987*F4987*(1-G4987) -> 5063.4 | K4987: =DATE(YEAR(B4987),MONTH(B4987),1) -> 45931 | L4987: =VLOOKUP(C4987,Customers!$A$2:$F$401,3,FALSE) -> Ismailia | M4987: =VLOOKUP(C4987,Customers!$A$2:$F$401,5,FALSE) -> Consumer | N4987: =VLOOKUP(D4987,Products!$A$2:$F$21,2,FALSE) -> Webcam HD | O4987: =VLOOKUP(D8,Products!$A$2:$F$21,4,FALSE) -> Office | P4987: =VLOOKUP(D4987,Products!$A$2:$F$21,3,FALSE) -> Accessories | Q4987: =VLOOKUP(D4987,Products!$A$2:$F$21,6,FALSE) -> 790 | R4987: =E4987*Q4987 -> 3160 | S4987: =J4987-R4987 -> 1903.4
A4988: ORD104986 | B4988: 45960 | C4988: C0012 | D4988: P016 | E4988: 2 | F4988: 252.2 | G4988: 0.2 | H4988: Cancelled | I4988: 5 | J4988: =E4988*F4988*(1-G4988) -> 403.52 | K4988: =DATE(YEAR(B4988),MONTH(B4988),1) -> 45931 | L4988: =VLOOKUP(C4988,Customers!$A$2:$F$401,3,FALSE) -> Shubra El-Kheima | M4988: =VLOOKUP(C4988,Customers!$A$2:$F$401,5,FALSE) -> Small Business | N4988: =VLOOKUP(D4988,Products!$A$2:$F$21,2,FALSE) -> Paper A4 Box | O4988: =VLOOKUP(D9,Products!$A$2:$F$21,4,FALSE) -> Office | P4988: =VLOOKUP(D4988,Products!$A$2:$F$21,3,FALSE) -> Stationery | Q4988: =VLOOKUP(D4988,Products!$A$2:$F$21,6,FALSE) -> 145 | R4988: =E4988*Q4988 -> 290 | S4988: =J4988-R4988 -> 113.52
A4989: ORD104987 | B4989: 45462 | C4989: C0198 | D4989: P017 | E4989: 1 | F4989: 3783 | G4989: 0.03 | H4989: Cancelled | I4989: 6 | J4989: =E4989*F4989*(1-G4989) -> 3669.51 | K4989: =DATE(YEAR(B4989),MONTH(B4989),1) -> 45444 | L4989: =VLOOKUP(C4989,Customers!$A$2:$F$401,3,FALSE) -> Banha | M4989: =VLOOKUP(C4989,Customers!$A$2:$F$401,5,FALSE) -> Consumer | N4989: =VLOOKUP(D4989,Products!$A$2:$F$21,2,FALSE) -> Filing Cabinet | O4989: =VLOOKUP(D10,Products!$A$2:$F$21,4,FALSE) -> Electronics | P4989: =VLOOKUP(D4989,Products!$A$2:$F$21,3,FALSE) -> Furniture | Q4989: =VLOOKUP(D4989,Products!$A$2:$F$21,6,FALSE) -> 2650 | R4989: =E4989*Q4989 -> 2650 | S4989: =J4989-R4989 -> 1019.51
A4990: ORD104988 | B4990: 45630 | C4990: C0187 | D4990: P016 | E4990: 4 | F4990: 260 | G4990: 0.05 | H4990: Completed | I4990: 4 | J4990: =E4990*F4990*(1-G4990) -> 988 | K4990: =DATE(YEAR(B4990),MONTH(B4990),1) -> 45627 | L4990: =VLOOKUP(C4990,Customers!$A$2:$F$401,3,FALSE) -> Banha | M4990: =VLOOKUP(C4990,Customers!$A$2:$F$401,5,FALSE) -> Corporate | N4990: =VLOOKUP(D4990,Products!$A$2:$F$21,2,FALSE) -> Paper A4 Box | O4990: =VLOOKUP(D11,Products!$A$2:$F$21,4,FALSE) -> Electronics | P4990: =VLOOKUP(D4990,Products!$A$2:$F$21,3,FALSE) -> Stationery | Q4990: =VLOOKUP(D4990,Products!$A$2:$F$21,6,FALSE) -> 145 | R4990: =E4990*Q4990 -> 580 | S4990: =J4990-R4990 -> 408
...

Sheet Dashboard
A1: sales performance dashboard
A3: total net sales | C3: completed orders | E3: average order value | G3: total gross profit
A4: =Sales_Raw!U3 -> 68776978 | C4: =Sales_Raw!U4 -> 4419 | E4: =Sales_Raw!U6 -> 15563.923 | G4: =Sales_Raw!U19 -> 15116523
AD13: z
Y22: SS

Sheet Products
A1: ProductID | B1: ProductName | C1: SubCategory | D1: Category | E1: ListPrice_EGP | F1: UnitCost_EGP
A2: P001 | B2: Laptop Pro 14 | C2: Computers | D2: Electronics | E2: 28500 | F2: 22100
A3: P002 | B3: Laptop Basic 15 | C3: Computers | D3: Electronics | E3: 19500 | F3: 15100
A4: P003 | B4: Wireless Mouse | C4: Accessories | D4: Electronics | E4: 450 | F4: 210
A5: P004 | B5: Mechanical Keyboard | C5: Accessories | D5: Electronics | E5: 1850 | F5: 990
A6: P005 | B6: 27-inch Monitor | C6: Displays | D6: Electronics | E6: 6200 | F6: 4300
A7: P006 | B7: USB-C Hub | C7: Accessories | D7: Electronics | E7: 1250 | F7: 620
A8: P007 | B8: Office Chair | C8: Furniture | D8: Office | E8: 4800 | F8: 3150
A9: P008 | B9: Standing Desk | C9: Furniture | D9: Office | E9: 9200 | F9: 6500
A10: P009 | B10: Notebook Pack | C10: Stationery | D10: Office | E10: 180 | F10: 75
A11: P010 | B11: Laser Printer | C11: Printers | D11: Electronics | E11: 7400 | F11: 5600
A12: P011 | B12: Printer Toner | C12: Supplies | D12: Office | E12: 980 | F12: 510
A13: P012 | B13: External SSD 1TB | C13: Storage | D13: Electronics | E13: 3600 | F13: 2450
... A21: P020 | B21: UPS 1200VA | C21: Power | D21: Electronics | E21: 4100 | F21: 2950

Sheet Customers
A1: CustomerID | B1: CustomerName | C1: City | D1: Region | E1: Segment | F1: SignupDate
A2: C0001 | B2: Nada Hassan | C2: Port Said | D2: Port Said | E2: Consumer | F2: 45019
A3: C0002 | B3: Youssef Adel | C3: Giza | D3: Giza | E3: Small Business | F3: 45678
A4: C0003 | B4: Omar Nabil | C4: Mansoura | D4: Dakahlia | E4: Consumer | F4: 44753
A5: C0004 | B5: Mostafa Ibrahim | C5: Zagazig | D5: Sharqia | E5: Small Business | F5: 45711
A6: C0005 | B6: Mostafa Adel | C6: Asyut | D6: Asyut | E6: Small Business | F6: 45421
A7: C0006 | B7: Nour Kamal | C7: Fayoum | D7: Fayoum | E7: Consumer | F7: 44575
A8: C0007 | B8: Salma Adel | C8: Mansoura | D8: Dakahlia | E8: Consumer | F8: 44880
A9: C0008 | B9: Mostafa Younis | C9: Tanta | D9: Gharbia | E9: Consumer | F9: 45340
A10: C0009 | B10: Nada Said | C10: Tanta | D10: Gharbia | E10: Small Business | F10: 44650
A11: C0010 | B11: Karim Fathy | C11: Giza | D11: Giza | E11: Corporate | F11: 45337
A12: C0011 | B12: Omar Fathy | C12: Alexandria | D12: Alexandria | E12: Small Business | F12: 45828
A13: C0012 | B13: Farah Nabil | C13: Shubra El-Kheima | D13: Qalyubia | E13: Small Business | F13: 44655
... A401: C0400 | B401: Omar Farouk | C401: Asyut | D401: Asyut | E401: Consumer | F401: 45612

Sheet Project_Guide
A1: Project Step | B1: What you will do
A2: 1. Understand the business problem | B2: Act as a Data Analyst for a fictional Egyptian office/electronics retailer.
A3: 2. Inspect the source data | B3: Review Sales_Raw, Products, and Customers; check row counts, data types, duplicates, and category values.
A4: 3. Clean and prepare data | B4: Create a separate cleaned table; do not overwrite the raw source. Investigate invalid values and duplicates.
A5: 4. Create calculated columns | B5: Add Gross Sales, Discount Amount, Net Sales, Total Cost, Profit, and Profit Margin.
A6: 5. Analyze with PivotTables | B6: Answer business questions about monthly performance, products, cities/regions, customer segments, and order status.
A7: 6. Build a dashboard | B7: Create KPI cards and charts with clear titles and consistent formatting.
A8: 7. Write business insights | B8: Summarize the main findings and recommend practical actions.
A9: 8. Document the project for GitHub | B9: Save screenshots and a README describing the problem, tools, methods, findings, and recommendations.
